Workbook

Sheet Inventory
A1: UPC | B1: PRODUCT_GROUP | C1: PRODUCT_NAME | D1: SKU | E1: Fabric | F1: Gender | G1: Category | H1: Style | I1: Design | J1: Color | K1: Size | L1: TYPE_NAME_DETAIL_EN | M1: TYPE_NAME_GROUP | N1: Price
A2: 1002706198035 | B2: Concept | C2: Frame | D2: CCO-EDE-UNI-SOU-FRA-FRA-MIX-0 | E2: =_xlfn.TEXTBEFORE(_xlfn.TEXTAFTER(D2,"-"),"-") -> EDE | F2: =_xlfn.TEXTBEFORE(_xlfn.TEXTAFTER(D2,"-",2),"-") -> UNI | G2: =_xlfn.TEXTBEFORE(_xlfn.TEXTAFTER(D2,"-",3),"-") -> SOU | H2: =_xlfn.TEXTBEFORE(_xlfn.TEXTAFTER(D2,"-",4),"-") -> FRA | I2: =_xlfn.TEXTBEFORE(_xlfn.TEXTAFTER(D2,"-",5),"-") -> FRA | J2: =_xlfn.TEXTBEFORE(_xlfn.TEXTAFTER(D2,"-",6),"-") -> MIX | K2: =_xlfn.TEXTAFTER(D2,"-",7) -> 0 | L2: 0 | M2: Other | N2: =_xlfn.XLOOKUP(A2,[1]SKU!$A:$A,[1]SKU!$Z:$Z) -> 310000
A3: 1003881136072 | B3: Apparel | C3: Flying Stock | D3: GPR-GSL-WOM-TTS-ONE-FST-ORA-L | E3: =_xlfn.TEXTBEFORE(_xlfn.TEXTAFTER(D3,"-"),"-") -> GSL | F3: =_xlfn.TEXTBEFORE(_xlfn.TEXTAFTER(D3,"-",2),"-") -> WOM | G3: =_xlfn.TEXTBEFORE(_xlfn.TEXTAFTER(D3,"-",3),"-") -> TTS | H3: =_xlfn.TEXTBEFORE(_xlfn.TEXTAFTER(D3,"-",4),"-") -> ONE | I3: =_xlfn.TEXTBEFORE(_xlfn.TEXTAFTER(D3,"-",5),"-") -> FST | J3: =_xlfn.TEXTBEFORE(_xlfn.TEXTAFTER(D3,"-",6),"-") -> ORA | K3: =_xlfn.TEXTAFTER(D3,"-",7) -> L | L3: Tank Top Sleeveless | M3: Tank Top | N3: =_xlfn.XLOOKUP(A3,[1]SKU!$A:$A,[1]SKU!$Z:$Z) -> 750000
A4: 1008462507470 | B4: Apparel | C4: Flying Fish | D4: GPR-GCV-MEN-SIS-BUT-FLH-WHI-L | E4: =_xlfn.TEXTBEFORE(_xlfn.TEXTAFTER(D4,"-"),"-") -> GCV | F4: =_xlfn.TEXTBEFORE(_xlfn.TEXTAFTER(D4,"-",2),"-") -> MEN | G4: =_xlfn.TEXTBEFORE(_xlfn.TEXTAFTER(D4,"-",3),"-") -> SIS | H4: =_xlfn.TEXTBEFORE(_xlfn.TEXTAFTER(D4,"-",4),"-") -> BUT | I4: =_xlfn.TEXTBEFORE(_xlfn.TEXTAFTER(D4,"-",5),"-") -> FLH | J4: =_xlfn.TEXTBEFORE(_xlfn.TEXTAFTER(D4,"-",6),"-") -> WHI | K4: =_xlfn.TEXTAFTER(D4,"-",7) -> L | L4: Shirt Short Sleeves | M4: Shirt | N4: =_xlfn.XLOOKUP(A4,[1]SKU!$A:$A,[1]SKU!$Z:$Z) -> 1790000
A5: 1018774360946 | B5: Concept | C5: Constable | D5: CCO-DSP-UNI-BAG-HDB-CON-RGN-0 | E5: =_xlfn.TEXTBEFORE(_xlfn.TEXTAFTER(D5,"-"),"-") -> DSP | F5: =_xlfn.TEXTBEFORE(_xlfn.TEXTAFTER(D5,"-",2),"-") -> UNI | G5: =_xlfn.TEXTBEFORE(_xlfn.TEXTAFTER(D5,"-",3),"-") -> BAG | H5: =_xlfn.TEXTBEFORE(_xlfn.TEXTAFTER(D5,"-",4),"-") -> HDB | I5: =_xlfn.TEXTBEFORE(_xlfn.TEXTAFTER(D5,"-",5),"-") -> CON | J5: =_xlfn.TEXTBEFORE(_xlfn.TEXTAFTER(D5,"-",6),"-") -> RGN | K5: =_xlfn.TEXTAFTER(D5,"-",7) -> 0 | L5: 0 | M5: Other | N5: =_xlfn.XLOOKUP(A5,[1]SKU!$A:$A,[1]SKU!$Z:$Z) -> 12250000
A6: 1028616235707 | B6: Concept | C6: Bardot | D6: CCO-DSP-UNI-BAG-CLU-BAR-RED-0 | E6: =_xlfn.TEXTBEFORE(_xlfn.TEXTAFTER(D6,"-"),"-") -> DSP | F6: =_xlfn.TEXTBEFORE(_xlfn.TEXTAFTER(D6,"-",2),"-") -> UNI | G6: =_xlfn.TEXTBEFORE(_xlfn.TEXTAFTER(D6,"-",3),"-") -> BAG | H6: =_xlfn.TEXTBEFORE(_xlfn.TEXTAFTER(D6,"-",4),"-") -> CLU | I6: =_xlfn.TEXTBEFORE(_xlfn.TEXTAFTER(D6,"-",5),"-") -> BAR | J6: =_xlfn.TEXTBEFORE(_xlfn.TEXTAFTER(D6,"-",6),"-") -> RED | K6: =_xlfn.TEXTAFTER(D6,"-",7) -> 0 | L6: 0 | M6: Other | N6: =_xlfn.XLOOKUP(A6,[1]SKU!$A:$A,[1]SKU!$Z:$Z) -> 3300000
A7: 1029532505400 | B7: Concept | C7: Bardot | D7: CCO-DSP-UNI-BAG-CLU-BAR-PUR-0 | E7: =_xlfn.TEXTBEFORE(_xlfn.TEXTAFTER(D7,"-"),"-") -> DSP | F7: =_xlfn.TEXTBEFORE(_xlfn.TEXTAFTER(D7,"-",2),"-") -> UNI | G7: =_xlfn.TEXTBEFORE(_xlfn.TEXTAFTER(D7,"-",3),"-") -> BAG | H7: =_xlfn.TEXTBEFORE(_xlfn.TEXTAFTER(D7,"-",4),"-") -> CLU | I7: =_xlfn.TEXTBEFORE(_xlfn.TEXTAFTER(D7,"-",5),"-") -> BAR | J7: =_xlfn.TEXTBEFORE(_xlfn.TEXTAFTER(D7,"-",6),"-") -> PUR | K7: =_xlfn.TEXTAFTER(D7,"-",7) -> 0 | L7: 0 | M7: Other | N7: =_xlfn.XLOOKUP(A7,[1]SKU!$A:$A,[1]SKU!$Z:$Z) -> 3300000
A8: 1036704952177 | B8: Apparel | C8: Saigon Traffic | D8: GPR-GBA-MEN-TSS-ONE-STC-WHI-XXL | E8: =_xlfn.TEXTBEFORE(_xlfn.TEXTAFTER(D8,"-"),"-") -> GBA | F8: =_xlfn.TEXTBEFORE(_xlfn.TEXTAFTER(D8,"-",2),"-") -> MEN | G8: =_xlfn.TEXTBEFORE(_xlfn.TEXTAFTER(D8,"-",3),"-") -> TSS | H8: =_xlfn.TEXTBEFORE(_xlfn.TEXTAFTER(D8,"-",4),"-") -> ONE | I8: =_xlfn.TEXTBEFORE(_xlfn.TEXTAFTER(D8,"-",5),"-") -> STC | J8: =_xlfn.TEXTBEFORE(_xlfn.TEXTAFTER(D8,"-",6),"-") -> WHI | K8: =_xlfn.TEXTAFTER(D8,"-",7) -> XXL | L8: T-Shirt Short Sleeves | M8: T-Shirt | N8: =_xlfn.XLOOKUP(A8,[1]SKU!$A:$A,[1]SKU!$Z:$Z) -> 710000
A9: 1037951943130 | B9: Art | C9: CA PARADISE ZOOM LEFT | D9: CCO-PAS-UNI-ART-ART-CP1-MIX-A3 | E9: =_xlfn.TEXTBEFORE(_xlfn.TEXTAFTER(D9,"-"),"-") -> PAS | F9: =_xlfn.TEXTBEFORE(_xlfn.TEXTAFTER(D9,"-",2),"-") -> UNI | G9: =_xlfn.TEXTBEFORE(_xlfn.TEXTAFTER(D9,"-",3),"-") -> ART | H9: =_xlfn.TEXTBEFORE(_xlfn.TEXTAFTER(D9,"-",4),"-") -> ART | I9: =_xlfn.TEXTBEFORE(_xlfn.TEXTAFTER(D9,"-",5),"-") -> CP1 | J9: =_xlfn.TEXTBEFORE(_xlfn.TEXTAFTER(D9,"-",6),"-") -> MIX | K9: =_xlfn.TEXTAFTER(D9,"-",7) -> A3 | L9: 0 | M9: Other | N9: =_xlfn.XLOOKUP(A9,[1]SKU!$A:$A,[1]SKU!$Z:$Z) -> 5000000
A10: 1040317153234 | B10: Apparel | C10: Star map | D10: GPR-GOR-MEN-TSS-ONE-SMP-BLK-M | E10: =_xlfn.TEXTBEFORE(_xlfn.TEXTAFTER(D10,"-"),"-") -> GOR | F10: =_xlfn.TEXTBEFORE(_xlfn.TEXTAFTER(D10,"-",2),"-") -> MEN | G10: =_xlfn.TEXTBEFORE(_xlfn.TEXTAFTER(D10,"-",3),"-") -> TSS | H10: =_xlfn.TEXTBEFORE(_xlfn.TEXTAFTER(D10,"-",4),"-") -> ONE | I10: =_xlfn.TEXTBEFORE(_xlfn.TEXTAFTER(D10,"-",5),"-") -> SMP | J10: =_xlfn.TEXTBEFORE(_xlfn.TEXTAFTER(D10,"-",6),"-") -> BLK | K10: =_xlfn.TEXTAFTER(D10,"-",7) -> M | L10: T-Shirt Short Sleeves | M10: T-Shirt | N10: =_xlfn.XLOOKUP(A10,[1]SKU!$A:$A,[1]SKU!$Z:$Z) -> 790000
A11: 1044940745071 | B11: Accessories | C11: Headband | D11: GPR-OTH-UNI-HWR-HEA-MIX-MIX-0 | E11: =_xlfn.TEXTBEFORE(_xlfn.TEXTAFTER(D11,"-"),"-") -> OTH | F11: =_xlfn.TEXTBEFORE(_xlfn.TEXTAFTER(D11,"-",2),"-") -> UNI | G11: =_xlfn.TEXTBEFORE(_xlfn.TEXTAFTER(D11,"-",3),"-") -> HWR | H11: =_xlfn.TEXTBEFORE(_xlfn.TEXTAFTER(D11,"-",4),"-") -> HEA | I11: =_xlfn.TEXTBEFORE(_xlfn.TEXTAFTER(D11,"-",5),"-") -> MIX | J11: =_xlfn.TEXTBEFORE(_xlfn.TEXTAFTER(D11,"-",6),"-") -> MIX | K11: =_xlfn.TEXTAFTER(D11,"-",7) -> 0 | L11: 0 | M11: Other | N11: =_xlfn.XLOOKUP(A11,[1]SKU!$A:$A,[1]SKU!$Z:$Z) -> 105000
A12: 1053187208201 | B12: Apparel | C12: Urban | D12: GPR-GOR-MEN-TSS-ONE-URB-JBG-L | E12: =_xlfn.TEXTBEFORE(_xlfn.TEXTAFTER(D12,"-"),"-") -> GOR | F12: =_xlfn.TEXTBEFORE(_xlfn.TEXTAFTER(D12,"-",2),"-") -> MEN | G12: =_xlfn.TEXTBEFORE(_xlfn.TEXTAFTER(D12,"-",3),"-") -> TSS | H12: =_xlfn.TEXTBEFORE(_xlfn.TEXTAFTER(D12,"-",4),"-") -> ONE | I12: =_xlfn.TEXTBEFORE(_xlfn.TEXTAFTER(D12,"-",5),"-") -> URB | J12: =_xlfn.TEXTBEFORE(_xlfn.TEXTAFTER(D12,"-",6),"-") -> JBG | K12: =_xlfn.TEXTAFTER(D12,"-",7) -> L | L12: T-Shirt Short Sleeves | M12: T-Shirt | N12: =_xlfn.XLOOKUP(A12,[1]SKU!$A:$A,[1]SKU!$Z:$Z) -> 790000
A13: 1061114435798 | B13: Concept | C13: Khăn 2M Truyen Kieu 70x70 | D13: CCO-LAN-UNI-HWR-SC2-TKU-PIN-70x70 | E13: =_xlfn.TEXTBEFORE(_xlfn.TEXTAFTER(D13,"-"),"-") -> LAN | F13: =_xlfn.TEXTBEFORE(_xlfn.TEXTAFTER(D13,"-",2),"-") -> UNI | G13: =_xlfn.TEXTBEFORE(_xlfn.TEXTAFTER(D13,"-",3),"-") -> HWR | H13: =_xlfn.TEXTBEFORE(_xlfn.TEXTAFTER(D13,"-",4),"-") -> SC2 | I13: =_xlfn.TEXTBEFORE(_xlfn.TEXTAFTER(D13,"-",5),"-") -> TKU | J13: =_xlfn.TEXTBEFORE(_xlfn.TEXTAFTER(D13,"-",6),"-") -> PIN | K13: =_xlfn.TEXTAFTER(D13,"-",7) -> 70x70 | L13: 0 | M13: Other | N13: =_xlfn.XLOOKUP(A13,[1]SKU!$A:$A,[1]SKU!$Z:$Z) -> 749000
A14: 1067914257486 | B14: Apparel | C14: Autumn Lion | D14: GPR-GSL-KID-TSS-ONE-AUL-WHI-10 | E14: =_xlfn.TEXTBEFORE(_xlfn.TEXTAFTER(D14,"-"),"-") -> GSL | F14: =_xlfn.TEXTBEFORE(_xlfn.TEXTAFTER(D14,"-",2),"-") -> KID | G14: =_xlfn.TEXTBEFORE(_xlfn.TEXTAFTER(D14,"-",3),"-") -> TSS | H14: =_xlfn.TEXTBEFORE(_xlfn.TEXTAFTER(D14,"-",4),"-") -> ONE | I14: =_xlfn.TEXTBEFORE(_xlfn.TEXTAFTER(D14,"-",5),"-") -> AUL | J14: =_xlfn.TEXTBEFORE(_xlfn.TEXTAFTER(D14,"-",6),"-") -> WHI | K14: =_xlfn.TEXTAFTER(D14,"-",7) -> 10 | L14: T-Shirt Short Sleeves | M14: T-Shirt | N14: =_xlfn.XLOOKUP(A14,[1]SKU!$A:$A,[1]SKU!$Z:$Z) -> 650000
A15: 1068272385279 | B15: Apparel | C15: Shuttlecock | D15: GPR-GSP-MEN-POL-MAN-SHU-NAV-S | E15: =_xlfn.TEXTBEFORE(_xlfn.TEXTAFTER(D15,"-"),"-") -> GSP | F15: =_xlfn.TEXTBEFORE(_xlfn.TEXTAFTER(D15,"-",2),"-") -> MEN | G15: =_xlfn.TEXTBEFORE(_xlfn.TEXTAFTER(D15,"-",3),"-") -> POL | H15: =_xlfn.TEXTBEFORE(_xlfn.TEXTAFTER(D15,"-",4),"-") -> MAN | I15: =_xlfn.TEXTBEFORE(_xlfn.TEXTAFTER(D15,"-",5),"-") -> SHU | J15: =_xlfn.TEXTBEFORE(_xlfn.TEXTAFTER(D15,"-",6),"-") -> NAV | K15: =_xlfn.TEXTAFTER(D15,"-",7) -> S | L15: Polo Short sleeves | M15: Polo | N15: =_xlfn.XLOOKUP(A15,[1]SKU!$A:$A,[1]SKU!$Z:$Z) -> 1090000
A16: 1075263734800 | B16: Concept | C16: Damascus M390 Santoku 18cm | D16: CPU-VNE-UNI-SOU-DAS-SAN-SGR-18CM | E16: =_xlfn.TEXTBEFORE(_xlfn.TEXTAFTER(D16,"-"),"-") -> VNE | F16: =_xlfn.TEXTBEFORE(_xlfn.TEXTAFTER(D16,"-",2),"-") -> UNI | G16: =_xlfn.TEXTBEFORE(_xlfn.TEXTAFTER(D16,"-",3),"-") -> SOU | H16: =_xlfn.TEXTBEFORE(_xlfn.TEXTAFTER(D16,"-",4),"-") -> DAS | I16: =_xlfn.TEXTBEFORE(_xlfn.TEXTAFTER(D16,"-",5),"-") -> SAN | J16: =_xlfn.TEXTBEFORE(_xlfn.TEXTAFTER(D16,"-",6),"-") -> SGR | K16: =_xlfn.TEXTAFTER(D16,"-",7) -> 18CM | L16: 0 | M16: Other | N16: =_xlfn.XLOOKUP(A16,[1]SKU!$A:$A,[1]SKU!$Z:$Z) -> 12500000
A17: 1078842893035 | B17: Apparel | C17: Vietnam Telecom | D17: GPR-GOR-MEN-TSS-ONE-VTM-GRE-XXL | E17: =_xlfn.TEXTBEFORE(_xlfn.TEXTAFTER(D17,"-"),"-") -> GOR | F17: =_xlfn.TEXTBEFORE(_xlfn.TEXTAFTER(D17,"-",2),"-") -> MEN | G17: =_xlfn.TEXTBEFORE(_xlfn.TEXTAFTER(D17,"-",3),"-") -> TSS | H17: =_xlfn.TEXTBEFORE(_xlfn.TEXTAFTER(D17,"-",4),"-") -> ONE | I17: =_xlfn.TEXTBEFORE(_xlfn.TEXTAFTER(D17,"-",5),"-") -> VTM | J17: =_xlfn.TEXTBEFORE(_xlfn.TEXTAFTER(D17,"-",6),"-") -> GRE | K17: =_xlfn.TEXTAFTER(D17,"-",7) -> XXL | L17: T-Shirt Short Sleeves | M17: T-Shirt | N17: =_xlfn.XLOOKUP(A17,[1]SKU!$A:$A,[1]SKU!$Z:$Z) -> 790000
A18: 1087844862079 | B18: Art | C18: FRAME | D18: CCO-PAS-UNI-ART-ART-FRA-MIX-AG | E18: =_xlfn.TEXTBEFORE(_xlfn.TEXTAFTER(D18,"-"),"-") -> PAS | F18: =_xlfn.TEXTBEFORE(_xlfn.TEXTAFTER(D18,"-",2),"-") -> UNI | G18: =_xlfn.TEXTBEFORE(_xlfn.TEXTAFTER(D18,"-",3),"-") -> ART | H18: =_xlfn.TEXTBEFORE(_xlfn.TEXTAFTER(D18,"-",4),"-") -> ART | I18: =_xlfn.TEXTBEFORE(_xlfn.TEXTAFTER(D18,"-",5),"-") -> FRA | J18: =_xlfn.TEXTBEFORE(_xlfn.TEXTAFTER(D18,"-",6),"-") -> MIX | K18: =_xlfn.TEXTAFTER(D18,"-",7) -> AG | L18: 0 | M18: Other | N18: =_xlfn.XLOOKUP(A18,[1]SKU!$A:$A,[1]SKU!$Z:$Z) -> 1000000
A19: 1102806988670 | B19: Concept | C19: Sitting Buddha | D19: CPU-PSD-UNI-SOU-DEC-SIB-BRO-8 | E19: =_xlfn.TEXTBEFORE(_xlfn.TEXTAFTER(D19,"-"),"-") -> PSD | F19: =_xlfn.TEXTBEFORE(_xlfn.TEXTAFTER(D19,"-",2),"-") -> UNI | G19: =_xlfn.TEXTBEFORE(_xlfn.TEXTAFTER(D19,"-",3),"-") -> SOU | H19: =_xlfn.TEXTBEFORE(_xlfn.TEXTAFTER(D19,"-",4),"-") -> DEC | I19: =_xlfn.TEXTBEFORE(_xlfn.TEXTAFTER(D19,"-",5),"-") -> SIB | J19: =_xlfn.TEXTBEFORE(_xlfn.TEXTAFTER(D19,"-",6),"-") -> BRO | K19: =_xlfn.TEXTAFTER(D19,"-",7) -> 8 | L19: 0 | M19: Other | N19: =_xlfn.XLOOKUP(A19,[1]SKU!$A:$A,[1]SKU!$Z:$Z) -> 290000
A20: 1103930901535 | B20: Apparel | C20: Logo | D20: GPR-GPI-MEN-POL-MAN-LOG-AGD-S | E20: =_xlfn.TEXTBEFORE(_xlfn.TEXTAFTER(D20,"-"),"-") -> GPI | F20: =_xlfn.TEXTBEFORE(_xlfn.TEXTAFTER(D20,"-",2),"-") -> MEN | G20: =_xlfn.TEXTBEFORE(_xlfn.TEXTAFTER(D20,"-",3),"-") -> POL | H20: =_xlfn.TEXTBEFORE(_xlfn.TEXTAFTER(D20,"-",4),"-") -> MAN | I20: =_xlfn.TEXTBEFORE(_xlfn.TEXTAFTER(D20,"-",5),"-") -> LOG | J20: =_xlfn.TEXTBEFORE(_xlfn.TEXTAFTER(D20,"-",6),"-") -> AGD | K20: =_xlfn.TEXTAFTER(D20,"-",7) -> S | L20: Polo Short sleeves | M20: Polo | N20: =_xlfn.XLOOKUP(A20,[1]SKU!$A:$A,[1]SKU!$Z:$Z) -> 1190000
A21: 1105872563871 | B21: Concept | C21: Cora I | D21: CCO-DSP-UNI-FWR-FLA-CO1-HOE-37 | E21: =_xlfn.TEXTBEFORE(_xlfn.TEXTAFTER(D21,"-"),"-") -> DSP | F21: =_xlfn.TEXTBEFORE(_xlfn.TEXTAFTER(D21,"-",2),"-") -> UNI | G21: =_xlfn.TEXTBEFORE(_xlfn.TEXTAFTER(D21,"-",3),"-") -> FWR | H21: =_xlfn.TEXTBEFORE(_xlfn.TEXTAFTER(D21,"-",4),"-") -> FLA | I21: =_xlfn.TEXTBEFORE(_xlfn.TEXTAFTER(D21,"-",5),"-") -> CO1 | J21: =_xlfn.TEXTBEFORE(_xlfn.TEXTAFTER(D21,"-",6),"-") -> HOE | K21: =_xlfn.TEXTAFTER(D21,"-",7) -> 37 | L21: 0 | M21: Other | N21: =_xlfn.XLOOKUP(A21,[1]SKU!$A:$A,[1]SKU!$Z:$Z) -> 5950000
A22: 1113470118409 | B22: Apparel | C22: The Eight Horses of Triumph | D22: GPR-GSU-WOM-TTB-BNE-EHT-YEL-M | E22: =_xlfn.TEXTBEFORE(_xlfn.TEXTAFTER(D22,"-"),"-") -> GSU | F22: =_xlfn.TEXTBEFORE(_xlfn.TEXTAFTER(D22,"-",2),"-") -> WOM | G22: =_xlfn.TEXTBEFORE(_xlfn.TEXTAFTER(D22,"-",3),"-") -> TTB | H22: =_xlfn.TEXTBEFORE(_xlfn.TEXTAFTER(D22,"-",4),"-") -> BNE | I22: =_xlfn.TEXTBEFORE(_xlfn.TEXTAFTER(D22,"-",5),"-") -> EHT | J22: =_xlfn.TEXTBEFORE(_xlfn.TEXTAFTER(D22,"-",6),"-") -> YEL | K22: =_xlfn.TEXTAFTER(D22,"-",7) -> M | L22: Tanktop Open Back | M22: Tank Top | N22: =_xlfn.XLOOKUP(A22,[1]SKU!$A:$A,[1]SKU!$Z:$Z) -> 950000
A23: 1113524387249 | B23: Apparel | C23: Di Dau | D23: GPR-GOR-MEN-TSS-ONE-DDU-GRE-M | E23: =_xlfn.TEXTBEFORE(_xlfn.TEXTAFTER(D23,"-"),"-") -> GOR | F23: =_xlfn.TEXTBEFORE(_xlfn.TEXTAFTER(D23,"-",2),"-") -> MEN | G23: =_xlfn.TEXTBEFORE(_xlfn.TEXTAFTER(D23,"-",3),"-") -> TSS | H23: =_xlfn.TEXTBEFORE(_xlfn.TEXTAFTER(D23,"-",4),"-") -> ONE | I23: =_xlfn.TEXTBEFORE(_xlfn.TEXTAFTER(D23,"-",5),"-") -> DDU | J23: =_xlfn.TEXTBEFORE(_xlfn.TEXTAFTER(D23,"-",6),"-") -> GRE | K23: =_xlfn.TEXTAFTER(D23,"-",7) -> M | L23: T-Shirt Short Sleeves | M23: T-Shirt | N23: =_xlfn.XLOOKUP(A23,[1]SKU!$A:$A,[1]SKU!$Z:$Z) -> 790000
A24: 1130035009057 | B24: Concept | C24: Khăn 2M Đoàn Thị Điểm 70x70 | D24: CCO-LAN-UNI-HWR-SC2-DTD-GRN-70x70 | E24: =_xlfn.TEXTBEFORE(_xlfn.TEXTAFTER(D24,"-"),"-") -> LAN | F24: =_xlfn.TEXTBEFORE(_xlfn.TEXTAFTER(D24,"-",2),"-") -> UNI | G24: =_xlfn.TEXTBEFORE(_xlfn.TEXTAFTER(D24,"-",3),"-") -> HWR | H24: =_xlfn.TEXTBEFORE(_xlfn.TEXTAFTER(D24,"-",4),"-") -> SC2 | I24: =_xlfn.TEXTBEFORE(_xlfn.TEXTAFTER(D24,"-",5),"-") -> DTD | J24: =_xlfn.TEXTBEFORE(_xlfn.TEXTAFTER(D24,"-",6),"-") -> GRN | K24: =_xlfn.TEXTAFTER(D24,"-",7) -> 70x70 | L24: 0 | M24: Other | N24: =_xlfn.XLOOKUP(A24,[1]SKU!$A:$A,[1]SKU!$Z:$Z) -> 749000
A25: 1134914281077 | B25: Concept | C25: Silk beads | D25: CCO-HAM-UNI-JEW-NEC-142-MIX-0 | E25: =_xlfn.TEXTBEFORE(_xlfn.TEXTAFTER(D25,"-"),"-") -> HAM | F25: =_xlfn.TEXTBEFORE(_xlfn.TEXTAFTER(D25,"-",2),"-") -> UNI | G25: =_xlfn.TEXTBEFORE(_xlfn.TEXTAFTER(D25,"-",3),"-") -> JEW | H25: =_xlfn.TEXTBEFORE(_xlfn.TEXTAFTER(D25,"-",4),"-") -> NEC | I25: =_xlfn.TEXTBEFORE(_xlfn.TEXTAFTER(D25,"-",5),"-") -> 142 | J25: =_xlfn.TEXTBEFORE(_xlfn.TEXTAFTER(D25,"-",6),"-") -> MIX | K25: =_xlfn.TEXTAFTER(D25,"-",7) -> 0 | L25: 0 | M25: Other | N25: =_xlfn.XLOOKUP(A25,[1]SKU!$A:$A,[1]SKU!$Z:$Z) -> 1800000
A26: 1145470298133 | B26: Apparel | C26: Gao | D26: GPR-GOR-MEN-TSS-HNE-GAO-BLK-L | E26: =_xlfn.TEXTBEFORE(_xlfn.TEXTAFTER(D26,"-"),"-") -> GOR | F26: =_xlfn.TEXTBEFORE(_xlfn.TEXTAFTER(D26,"-",2),"-") -> MEN | G26: =_xlfn.TEXTBEFORE(_xlfn.TEXTAFTER(D26,"-",3),"-") -> TSS | H26: =_xlfn.TEXTBEFORE(_xlfn.TEXTAFTER(D26,"-",4),"-") -> HNE | I26: =_xlfn.TEXTBEFORE(_xlfn.TEXTAFTER(D26,"-",5),"-") -> GAO | J26: =_xlfn.TEXTBEFORE(_xlfn.TEXTAFTER(D26,"-",6),"-") -> BLK | K26: =_xlfn.TEXTAFTER(D26,"-",7) -> L | L26: T-Shirt Short Sleeves | M26: T-Shirt | N26: =_xlfn.XLOOKUP(A26,[1]SKU!$A:$A,[1]SKU!$Z:$Z) -> 1650000
A27: 1145867173203 | B27: Art | C27: FRAME | D27: CCO-PAS-UNI-ART-ART-FRA-MIX-A1 | E27: =_xlfn.TEXTBEFORE(_xlfn.TEXTAFTER(D27,"-"),"-") -> PAS | F27: =_xlfn.TEXTBEFORE(_xlfn.TEXTAFTER(D27,"-",2),"-") -> UNI | G27: =_xlfn.TEXTBEFORE(_xlfn.TEXTAFTER(D27,"-",3),"-") -> ART | H27: =_xlfn.TEXTBEFORE(_xlfn.TEXTAFTER(D27,"-",4),"-") -> ART | I27: =_xlfn.TEXTBEFORE(_xlfn.TEXTAFTER(D27,"-",5),"-") -> FRA | J27: =_xlfn.TEXTBEFORE(_xlfn.TEXTAFTER(D27,"-",6),"-") -> MIX | K27: =_xlfn.TEXTAFTER(D27,"-",7) -> A1 | L27: 0 | M27: Other | N27: =_xlfn.XLOOKUP(A27,[1]SKU!$A:$A,[1]SKU!$Z:$Z) -> 2500000
A28: 1148733069105 | B28: Art | C28: HER HAIR, THE LAST REFUGE | D28: CCO-PAS-UNI-ART-ART-HHR-MIX-A1 | E28: =_xlfn.TEXTBEFORE(_xlfn.TEXTAFTER(D28,"-"),"-") -> PAS | F28: =_xlfn.TEXTBEFORE(_xlfn.TEXTAFTER(D28,"-",2),"-") -> UNI | G28: =_xlfn.TEXTBEFORE(_xlfn.TEXTAFTER(D28,"-",3),"-") -> ART | H28: =_xlfn.TEXTBEFORE(_xlfn.TEXTAFTER(D28,"-",4),"-") -> ART | I28: =_xlfn.TEXTBEFORE(_xlfn.TEXTAFTER(D28,"-",5),"-") -> HHR | J28: =_xlfn.TEXTBEFORE(_xlfn.TEXTAFTER(D28,"-",6),"-") -> MIX | K28: =_xlfn.TEXTAFTER(D28,"-",7) -> A1 | L28: 0 | M28: Other | N28: =_xlfn.XLOOKUP(A28,[1]SKU!$A:$A,[1]SKU!$Z:$Z) -> 7500000
A29: 1150392641639 | B29: Concept | C29: Schaeffer | D29: CCO-DSP-UNI-BAG-CHR-SCH-BWH-0 | E29: =_xlfn.TEXTBEFORE(_xlfn.TEXTAFTER(D29,"-"),"-") -> DSP | F29: =_xlfn.TEXTBEFORE(_xlfn.TEXTAFTER(D29,"-",2),"-") -> UNI | G29: =_xlfn.TEXTBEFORE(_xlfn.TEXTAFTER(D29,"-",3),"-") -> BAG | H29: =_xlfn.TEXTBEFORE(_xlfn.TEXTAFTER(D29,"-",4),"-") -> CHR | I29: =_xlfn.TEXTBEFORE(_xlfn.TEXTAFTER(D29,"-",5),"-") -> SCH | J29: =_xlfn.TEXTBEFORE(_xlfn.TEXTAFTER(D29,"-",6),"-") -> BWH | K29: =_xlfn.TEXTAFTER(D29,"-",7) -> 0 | L29: 0 | M29: Other | N29: =_xlfn.XLOOKUP(A29,[1]SKU!$A:$A,[1]SKU!$Z:$Z) -> 1150000
A30: 1159525763002 | B30: Concept | C30: Silk beads, Enamel | D30: CCO-HAM-UNI-JEW-NEC-A29-MIX-0 | E30: =_xlfn.TEXTBEFORE(_xlfn.TEXTAFTER(D30,"-"),"-") -> HAM | F30: =_xlfn.TEXTBEFORE(_xlfn.TEXTAFTER(D30,"-",2),"-") -> UNI | G30: =_xlfn.TEXTBEFORE(_xlfn.TEXTAFTER(D30,"-",3),"-") -> JEW | H30: =_xlfn.TEXTBEFORE(_xlfn.TEXTAFTER(D30,"-",4),"-") -> NEC | I30: =_xlfn.TEXTBEFORE(_xlfn.TEXTAFTER(D30,"-",5),"-") -> A29 | J30: =_xlfn.TEXTBEFORE(_xlfn.TEXTAFTER(D30,"-",6),"-") -> MIX | K30: =_xlfn.TEXTAFTER(D30,"-",7) -> 0 | L30: 0 | M30: Other | N30: =_xlfn.XLOOKUP(A30,[1]SKU!$A:$A,[1]SKU!$Z:$Z) -> 1800000
A31: 1164868917173 | B31: Concept | C31: Silk beads, Enamel | D31: CCO-HAM-UNI-JEW-NEC-076-MIX-0 | E31: =_xlfn.TEXTBEFORE(_xlfn.TEXTAFTER(D31,"-"),"-") -> HAM | F31: =_xlfn.TEXTBEFORE(_xlfn.TEXTAFTER(D31,"-",2),"-") -> UNI | G31: =_xlfn.TEXTBEFORE(_xlfn.TEXTAFTER(D31,"-",3),"-") -> JEW | H31: =_xlfn.TEXTBEFORE(_xlfn.TEXTAFTER(D31,"-",4),"-") -> NEC | I31: =_xlfn.TEXTBEFORE(_xlfn.TEXTAFTER(D31,"-",5),"-") -> 076 | J31: =_xlfn.TEXTBEFORE(_xlfn.TEXTAFTER(D31,"-",6),"-") -> MIX | K31: =_xlfn.TEXTAFTER(D31,"-",7) -> 0 | L31: 0 | M31: Other | N31: =_xlfn.XLOOKUP(A31,[1]SKU!$A:$A,[1]SKU!$Z:$Z) -> 1800000
A32: 1165815805543 | B32: Accessories | C32: Lily Pattern | D32: GPR-OTH-UNI-HWR-CAP-LPN-BOR-S | E32: =_xlfn.TEXTBEFORE(_xlfn.TEXTAFTER(D32,"-"),"-") -> OTH | F32: =_xlfn.TEXTBEFORE(_xlfn.TEXTAFTER(D32,"-",2),"-") -> UNI | G32: =_xlfn.TEXTBEFORE(_xlfn.TEXTAFTER(D32,"-",3),"-") -> HWR | H32: =_xlfn.TEXTBEFORE(_xlfn.TEXTAFTER(D32,"-",4),"-") -> CAP | I32: =_xlfn.TEXTBEFORE(_xlfn.TEXTAFTER(D32,"-",5),"-") -> LPN | J32: =_xlfn.TEXTBEFORE(_xlfn.TEXTAFTER(D32,"-",6),"-") -> BOR | K32: =_xlfn.TEXTAFTER(D32,"-",7) -> S | L32: 0 | M32: Other | N32: =_xlfn.XLOOKUP(A32,[1]SKU!$A:$A,[1]SKU!$Z:$Z) -> 370000
A33: 1170845549305 | B33: Apparel | C33: Linen Pants | D33: GPR-GLI-MEN-PAF-BBT-LIN-WHI-XL | E33: =_xlfn.TEXTBEFORE(_xlfn.TEXTAFTER(D33,"-"),"-") -> GLI | F33: =_xlfn.TEXTBEFORE(_xlfn.TEXTAFTER(D33,"-",2),"-") -> MEN | G33: =_xlfn.TEXTBEFORE(_xlfn.TEXTAFTER(D33,"-",3),"-") -> PAF | H33: =_xlfn.TEXTBEFORE(_xlfn.TEXTAFTER(D33,"-",4),"-") -> BBT | I33: =_xlfn.TEXTBEFORE(_xlfn.TEXTAFTER(D33,"-",5),"-") -> LIN | J33: =_xlfn.TEXTBEFORE(_xlfn.TEXTAFTER(D33,"-",6),"-") -> WHI | K33: =_xlfn.TEXTAFTER(D33,"-",7) -> XL | L33: Pants slim fit | M33: Pants | N33: =_xlfn.XLOOKUP(A33,[1]SKU!$A:$A,[1]SKU!$Z:$Z) -> 2690000
A34: 1180395777400 | B34: Apparel | C34: Red Lantern | D34: GPR-GPI-MEN-POL-MAN-RLN-OLI-S | E34: =_xlfn.TEXTBEFORE(_xlfn.TEXTAFTER(D34,"-"),"-") -> GPI | F34: =_xlfn.TEXTBEFORE(_xlfn.TEXTAFTER(D34,"-",2),"-") -> MEN | G34: =_xlfn.TEXTBEFORE(_xlfn.TEXTAFTER(D34,"-",3),"-") -> POL | H34: =_xlfn.TEXTBEFORE(_xlfn.TEXTAFTER(D34,"-",4),"-") -> MAN | I34: =_xlfn.TEXTBEFORE(_xlfn.TEXTAFTER(D34,"-",5),"-") -> RLN | J34: =_xlfn.TEXTBEFORE(_xlfn.TEXTAFTER(D34,"-",6),"-") -> OLI | K34: =_xlfn.TEXTAFTER(D34,"-",7) -> S | L34: Polo Short sleeves | M34: Polo | N34: =_xlfn.XLOOKUP(A34,[1]SKU!$A:$A,[1]SKU!$Z:$Z) -> 1190000
A35: 1182703260376 | B35: Accessories | C35: Notebook Hoi an | D35: GPR-OTH-UNI-SOU-NBI-HAI-MIX-A5 | E35: =_xlfn.TEXTBEFORE(_xlfn.TEXTAFTER(D35,"-"),"-") -> OTH | F35: =_xlfn.TEXTBEFORE(_xlfn.TEXTAFTER(D35,"-",2),"-") -> UNI | G35: =_xlfn.TEXTBEFORE(_xlfn.TEXTAFTER(D35,"-",3),"-") -> SOU | H35: =_xlfn.TEXTBEFORE(_xlfn.TEXTAFTER(D35,"-",4),"-") -> NBI | I35: =_xlfn.TEXTBEFORE(_xlfn.TEXTAFTER(D35,"-",5),"-") -> HAI | J35: =_xlfn.TEXTBEFORE(_xlfn.TEXTAFTER(D35,"-",6),"-") -> MIX | K35: =_xlfn.TEXTAFTER(D35,"-",7) -> A5 | L35: 0 | M35: Other | N35: =_xlfn.XLOOKUP(A35,[1]SKU!$A:$A,[1]SKU!$Z:$Z) -> 210000
A36: 1188206568438 | B36: Concept | C36: Silk beads, Enamel | D36: CCO-HAM-UNI-JEW-NEC-140-MIX-0 | E36: =_xlfn.TEXTBEFORE(_xlfn.TEXTAFTER(D36,"-"),"-") -> HAM | F36: =_xlfn.TEXTBEFORE(_xlfn.TEXTAFTER(D36,"-",2),"-") -> UNI | G36: =_xlfn.TEXTBEFORE(_xlfn.TEXTAFTER(D36,"-",3),"-") -> JEW | H36: =_xlfn.TEXTBEFORE(_xlfn.TEXTAFTER(D36,"-",4),"-") -> NEC | I36: =_xlfn.TEXTBEFORE(_xlfn.TEXTAFTER(D36,"-",5),"-") -> 140 | J36: =_xlfn.TEXTBEFORE(_xlfn.TEXTAFTER(D36,"-",6),"-") -> MIX | K36: =_xlfn.TEXTAFTER(D36,"-",7) -> 0 | L36: 0 | M36: Other | N36: =_xlfn.XLOOKUP(A36,[1]SKU!$A:$A,[1]SKU!$Z:$Z) -> 1800000
A37: 1192948041722 | B37: Apparel | C37: Wolf | D37: GPR-GOR-WOM-TTB-BNE-WOL-GRE-S | E37: =_xlfn.TEXTBEFORE(_xlfn.TEXTAFTER(D37,"-"),"-") -> GOR | F37: =_xlfn.TEXTBEFORE(_xlfn.TEXTAFTER(D37,"-",2),"-") -> WOM | G37: =_xlfn.TEXTBEFORE(_xlfn.TEXTAFTER(D37,"-",3),"-") -> TTB | H37: =_xlfn.TEXTBEFORE(_xlfn.TEXTAFTER(D37,"-",4),"-") -> BNE | I37: =_xlfn.TEXTBEFORE(_xlfn.TEXTAFTER(D37,"-",5),"-") -> WOL | J37: =_xlfn.TEXTBEFORE(_xlfn.TEXTAFTER(D37,"-",6),"-") -> GRE | K37: =_xlfn.TEXTAFTER(D37,"-",7) -> S | L37: Tanktop Open Back | M37: Tank Top | N37: =_xlfn.XLOOKUP(A37,[1]SKU!$A:$A,[1]SKU!$Z:$Z) -> 790000
A38: 1196268057401 | B38: CF | C38: Ruby Plum Tea | D38: GPR-GCF-UNI-FNB-CFO-RPT-MIX-0 | E38: =_xlfn.TEXTBEFORE(_xlfn.TEXTAFTER(D38,"-"),"-") -> GCF | F38: =_xlfn.TEXTBEFORE(_xlfn.TEXTAFTER(D38,"-",2),"-") -> UNI | G38: =_xlfn.TEXTBEFORE(_xlfn.TEXTAFTER(D38,"-",3),"-") -> FNB | H38: =_xlfn.TEXTBEFORE(_xlfn.TEXTAFTER(D38,"-",4),"-") -> CFO | I38: =_xlfn.TEXTBEFORE(_xlfn.TEXTAFTER(D38,"-",5),"-") -> RPT | J38: =_xlfn.TEXTBEFORE(_xlfn.TEXTAFTER(D38,"-",6),"-") -> MIX | K38: =_xlfn.TEXTAFTER(D38,"-",7) -> 0 | L38: 0 | M38: Other | N38: =_xlfn.XLOOKUP(A38,[1]SKU!$A:$A,[1]SKU!$Z:$Z) -> 75000
A39: 1210083593576 | B39: Concept | C39: Túi cầm tay loại lớn (Accessories Bag L) | D39: CCO-DSP-UNI-BAG-HDB-ABG-HGP-L | E39: =_xlfn.TEXTBEFORE(_xlfn.TEXTAFTER(D39,"-"),"-") -> DSP | F39: =_xlfn.TEXTBEFORE(_xlfn.TEXTAFTER(D39,"-",2),"-") -> UNI | G39: =_xlfn.TEXTBEFORE(_xlfn.TEXTAFTER(D39,"-",3),"-") -> BAG | H39: =_xlfn.TEXTBEFORE(_xlfn.TEXTAFTER(D39,"-",4),"-") -> HDB | I39: =_xlfn.TEXTBEFORE(_xlfn.TEXTAFTER(D39,"-",5),"-") -> ABG | J39: =_xlfn.TEXTBEFORE(_xlfn.TEXTAFTER(D39,"-",6),"-") -> HGP | K39: =_xlfn.TEXTAFTER(D39,"-",7) -> L | L39: 0 | M39: Other | N39: =_xlfn.XLOOKUP(A39,[1]SKU!$A:$A,[1]SKU!$Z:$Z) -> 4800000
A40: 1211280847608 | B40: Concept | C40: Aznavour I | D40: CCO-DSP-UNI-BAG-CCR-AZ1-DBN-0 | E40: =_xlfn.TEXTBEFORE(_xlfn.TEXTAFTER(D40,"-"),"-") -> DSP | F40: =_xlfn.TEXTBEFORE(_xlfn.TEXTAFTER(D40,"-",2),"-") -> UNI | G40: =_xlfn.TEXTBEFORE(_xlfn.TEXTAFTER(D40,"-",3),"-") -> BAG | H40: =_xlfn.TEXTBEFORE(_xlfn.TEXTAFTER(D40,"-",4),"-") -> CCR | I40: =_xlfn.TEXTBEFORE(_xlfn.TEXTAFTER(D40,"-",5),"-") -> AZ1 | J40: =_xlfn.TEXTBEFORE(_xlfn.TEXTAFTER(D40,"-",6),"-") -> DBN | K40: =_xlfn.TEXTAFTER(D40,"-",7) -> 0 | L40: 0 | M40: Other | N40: =_xlfn.XLOOKUP(A40,[1]SKU!$A:$A,[1]SKU!$Z:$Z) -> 2100000
...

Sheet Fabric
A1: Fabric | B1: Name
A2: EDE | B2: =_xlfn.XLOOKUP(A2,'Hướng dẫn'!$I$26:$I$67,'Hướng dẫn'!$G$26:$G$67) -> Eugemie Darge
A3: GSL | B3: =_xlfn.XLOOKUP(A3,'Hướng dẫn'!$I$26:$I$67,'Hướng dẫn'!$G$26:$G$67) -> Special
A4: GCV | B4: =_xlfn.XLOOKUP(A4,'Hướng dẫn'!$I$26:$I$67,'Hướng dẫn'!$G$26:$G$67) -> Cotton Veil
A5: DSP | B5: =_xlfn.XLOOKUP(A5,'Hướng dẫn'!$I$26:$I$67,'Hướng dẫn'!$G$26:$G$67) -> Dominique Saint Paul
A6: GBA | B6: =_xlfn.XLOOKUP(A6,'Hướng dẫn'!$I$26:$I$67,'Hướng dẫn'!$G$26:$G$67) -> Basic
A7: PAS | B7: =_xlfn.XLOOKUP(A7,'Hướng dẫn'!$I$26:$I$67,'Hướng dẫn'!$G$26:$G$67) -> PETTI CAFÉ
A8: GOR | B8: =_xlfn.XLOOKUP(A8,'Hướng dẫn'!$I$26:$I$67,'Hướng dẫn'!$G$26:$G$67) -> Organic
A9: OTH | B9: =_xlfn.XLOOKUP(A9,'Hướng dẫn'!$I$26:$I$67,'Hướng dẫn'!$G$26:$G$67) -> Other
A10: LAN | B10: =_xlfn.XLOOKUP(A10,'Hướng dẫn'!$I$26:$I$67,'Hướng dẫn'!$G$26:$G$67) -> La'Artisan
A11: GSP | B11: =_xlfn.XLOOKUP(A11,'Hướng dẫn'!$I$26:$I$67,'Hướng dẫn'!$G$26:$G$67) -> Spandex
A12: VNE | B12: =_xlfn.XLOOKUP(A12,'Hướng dẫn'!$I$26:$I$67,'Hướng dẫn'!$G$26:$G$67) -> Vietk nife
A13: PSD | B13: =_xlfn.XLOOKUP(A13,'Hướng dẫn'!$I$26:$I$67,'Hướng dẫn'!$G$26:$G$67) -> Product Simplizied
... A35: DI8 | B35: =_xlfn.XLOOKUP(A35,'Hướng dẫn'!$I$26:$I$67,'Hướng dẫn'!$G$26:$G$67) -> Ngôi nhà quận 8

Sheet Category
A1: Category | B1: Name
A2: SOU | B2: Souvernir
A3: TTS | B3: =IF(_xlfn.XLOOKUP(A3,'Hướng dẫn'!$U$27:$U$98,'Hướng dẫn'!$R$27:$R$98)=0,A3,_xlfn.XLOOKUP(A3,'Hướng dẫn'!$U$27:$U$98,'Hướng dẫn'!$R$27:$R$98)) -> Tank Top Sleeveless
A4: SIS | B4: =IF(_xlfn.XLOOKUP(A4,'Hướng dẫn'!$U$27:$U$98,'Hướng dẫn'!$R$27:$R$98)=0,A4,_xlfn.XLOOKUP(A4,'Hướng dẫn'!$U$27:$U$98,'Hướng dẫn'!$R$27:$R$98)) -> Shirt Short Sleeves
A5: BAG | B5: Bag
A6: TSS | B6: =IF(_xlfn.XLOOKUP(A6,'Hướng dẫn'!$U$27:$U$98,'Hướng dẫn'!$R$27:$R$98)=0,A6,_xlfn.XLOOKUP(A6,'Hướng dẫn'!$U$27:$U$98,'Hướng dẫn'!$R$27:$R$98)) -> T-Shirt Short Sleeves
A7: ART | B7: Art
A8: HWR | B8: Head Wear
A9: POL | B9: =IF(_xlfn.XLOOKUP(A9,'Hướng dẫn'!$U$27:$U$98,'Hướng dẫn'!$R$27:$R$98)=0,A9,_xlfn.XLOOKUP(A9,'Hướng dẫn'!$U$27:$U$98,'Hướng dẫn'!$R$27:$R$98)) -> Polo Short sleeves
A10: FWR | B10: Foot Wear
A11: TTB | B11: =IF(_xlfn.XLOOKUP(A11,'Hướng dẫn'!$U$27:$U$98,'Hướng dẫn'!$R$27:$R$98)=0,A11,_xlfn.XLOOKUP(A11,'Hướng dẫn'!$U$27:$U$98,'Hướng dẫn'!$R$27:$R$98)) -> Tanktop Open Back
A12: JEW | B12: Jewelry
A13: PAF | B13: =IF(_xlfn.XLOOKUP(A13,'Hướng dẫn'!$U$27:$U$98,'Hướng dẫn'!$R$27:$R$98)=0,A13,_xlfn.XLOOKUP(A13,'Hướng dẫn'!$U$27:$U$98,'Hướng dẫn'!$R$27:$R$98)) -> Pants slim fit
A14: FNB | B14: FNB
A15: APP | B15: =IF(_xlfn.XLOOKUP(A15,'Hướng dẫn'!$U$27:$U$98,'Hướng dẫn'!$R$27:$R$98)=0,A15,_xlfn.XLOOKUP(A15,'Hướng dẫn'!$U$27:$U$98,'Hướng dẫn'!$R$27:$R$98)) -> Apple
A16: HLS | B16: =IF(_xlfn.XLOOKUP(A16,'Hướng dẫn'!$U$27:$U$98,'Hướng dẫn'!$R$27:$R$98)=0,A16,_xlfn.XLOOKUP(A16,'Hướng dẫn'!$U$27:$U$98,'Hướng dẫn'!$R$27:$R$98)) -> Hoodies long sleeves
A17: TSP | B17: =IF(_xlfn.XLOOKUP(A17,'Hướng dẫn'!$U$27:$U$98,'Hướng dẫn'!$R$27:$R$98)=0,A17,_xlfn.XLOOKUP(A17,'Hướng dẫn'!$U$27:$U$98,'Hướng dẫn'!$R$27:$R$98)) -> T-shirts Pocket Short Sleeves
A18: COS | B18: Cosmetics
A19: PZE | B19: =IF(_xlfn.XLOOKUP(A19,'Hướng dẫn'!$U$27:$U$98,'Hướng dẫn'!$R$27:$R$98)=0,A19,_xlfn.XLOOKUP(A19,'Hướng dẫn'!$U$27:$U$98,'Hướng dẫn'!$R$27:$R$98)) -> Plus Size
A20: TSO | B20: =IF(_xlfn.XLOOKUP(A20,'Hướng dẫn'!$U$27:$U$98,'Hướng dẫn'!$R$27:$R$98)=0,A20,_xlfn.XLOOKUP(A20,'Hướng dẫn'!$U$27:$U$98,'Hướng dẫn'!$R$27:$R$98)) -> T-Shirt Oversized
A21: SHH | B21: =IF(_xlfn.XLOOKUP(A21,'Hướng dẫn'!$U$27:$U$98,'Hướng dẫn'!$R$27:$R$98)=0,A21,_xlfn.XLOOKUP(A21,'Hướng dẫn'!$U$27:$U$98,'Hướng dẫn'!$R$27:$R$98)) -> High waist Short
A22: HDR | B22: Home Décor
A23: TSB | B23: =IF(_xlfn.XLOOKUP(A23,'Hướng dẫn'!$U$27:$U$98,'Hướng dẫn'!$R$27:$R$98)=0,A23,_xlfn.XLOOKUP(A23,'Hướng dẫn'!$U$27:$U$98,'Hướng dẫn'!$R$27:$R$98)) -> T-Shirt Open Back
A24: CRO | B24: =IF(_xlfn.XLOOKUP(A24,'Hướng dẫn'!$U$27:$U$98,'Hướng dẫn'!$R$27:$R$98)=0,A24,_xlfn.XLOOKUP(A24,'Hướng dẫn'!$U$27:$U$98,'Hướng dẫn'!$R$27:$R$98)) -> Crop Top Short Sleeves Crew Neck Oversized
A25: SHS | B25: =IF(_xlfn.XLOOKUP(A25,'Hướng dẫn'!$U$27:$U$98,'Hướng dẫn'!$R$27:$R$98)=0,A25,_xlfn.XLOOKUP(A25,'Hướng dẫn'!$U$27:$U$98,'Hướng dẫn'!$R$27:$R$98)) -> Short men straight
A26: BLA | B26: =IF(_xlfn.XLOOKUP(A26,'Hướng dẫn'!$U$27:$U$98,'Hướng dẫn'!$R$27:$R$98)=0,A26,_xlfn.XLOOKUP(A26,'Hướng dẫn'!$U$27:$U$98,'Hướng dẫn'!$R$27:$R$98)) -> Blouse Long Sleeves Asymmetrical
A27: ACC | B27: Other Accessories
A28: SHD | B28: =IF(_xlfn.XLOOKUP(A28,'Hướng dẫn'!$U$27:$U$98,'Hướng dẫn'!$R$27:$R$98)=0,A28,_xlfn.XLOOKUP(A28,'Hướng dẫn'!$U$27:$U$98,'Hướng dẫn'!$R$27:$R$98)) -> Short women curved
A29: FZE | B29: =IF(_xlfn.XLOOKUP(A29,'Hướng dẫn'!$U$27:$U$98,'Hướng dẫn'!$R$27:$R$98)=0,A29,_xlfn.XLOOKUP(A29,'Hướng dẫn'!$U$27:$U$98,'Hướng dẫn'!$R$27:$R$98)) -> Freesize
A30: SWL | B30: =IF(_xlfn.XLOOKUP(A30,'Hướng dẫn'!$U$27:$U$98,'Hướng dẫn'!$R$27:$R$98)=0,A30,_xlfn.XLOOKUP(A30,'Hướng dẫn'!$U$27:$U$98,'Hướng dẫn'!$R$27:$R$98)) -> Sweatshirt long sleeves
A31: BLB | B31: =IF(_xlfn.XLOOKUP(A31,'Hướng dẫn'!$U$27:$U$98,'Hướng dẫn'!$R$27:$R$98)=0,A31,_xlfn.XLOOKUP(A31,'Hướng dẫn'!$U$27:$U$98,'Hướng dẫn'!$R$27:$R$98)) -> Blouse Open Back Short Sleeves
A32: SKS | B32: =IF(_xlfn.XLOOKUP(A32,'Hướng dẫn'!$U$27:$U$98,'Hướng dẫn'!$R$27:$R$98)=0,A32,_xlfn.XLOOKUP(A32,'Hướng dẫn'!$U$27:$U$98,'Hướng dẫn'!$R$27:$R$98)) -> Slit Pencil Skirt
A33: SCA | B33: Scarves
A34: BLC | B34: =IF(_xlfn.XLOOKUP(A34,'Hướng dẫn'!$U$27:$U$98,'Hướng dẫn'!$R$27:$R$98)=0,A34,_xlfn.XLOOKUP(A34,'Hướng dẫn'!$U$27:$U$98,'Hướng dẫn'!$R$27:$R$98)) -> Blouse Crop Top

Sheet Style
A1: Style | B1: Name
A2: FRA | B2: =_xlfn.XLOOKUP(A2,'Hướng dẫn'!AA:AA,'Hướng dẫn'!X:X) -> Frame
A3: ONE | B3: =_xlfn.XLOOKUP(A3,'Hướng dẫn'!AA:AA,'Hướng dẫn'!X:X) -> Crew neck classic
A4: BUT | B4: =_xlfn.XLOOKUP(A4,'Hướng dẫn'!AA:AA,'Hướng dẫn'!X:X) -> Button-down Collar
A5: HDB | B5: =_xlfn.XLOOKUP(A5,'Hướng dẫn'!AA:AA,'Hướng dẫn'!X:X) -> Handbag
A6: CLU | B6: =_xlfn.XLOOKUP(A6,'Hướng dẫn'!AA:AA,'Hướng dẫn'!X:X) -> Clutch
A7: CLU | B7: =_xlfn.XLOOKUP(A7,'Hướng dẫn'!AA:AA,'Hướng dẫn'!X:X) -> Clutch
A8: ONE | B8: =_xlfn.XLOOKUP(A8,'Hướng dẫn'!AA:AA,'Hướng dẫn'!X:X) -> Crew neck classic
A9: ART | B9: =_xlfn.XLOOKUP(A9,'Hướng dẫn'!AA:AA,'Hướng dẫn'!X:X) -> ART
A10: ONE | B10: =_xlfn.XLOOKUP(A10,'Hướng dẫn'!AA:AA,'Hướng dẫn'!X:X) -> Crew neck classic
A11: HEA | B11: =_xlfn.XLOOKUP(A11,'Hướng dẫn'!AA:AA,'Hướng dẫn'!X:X) -> Headband
A12: ONE | B12: =_xlfn.XLOOKUP(A12,'Hướng dẫn'!AA:AA,'Hướng dẫn'!X:X) -> Crew neck classic
A13: SC2 | B13: =_xlfn.XLOOKUP(A13,'Hướng dẫn'!AA:AA,'Hướng dẫn'!X:X) -> Scarf Satin Double Side Print
... A1610: ONE | B1610: =_xlfn.XLOOKUP(A1610,'Hướng dẫn'!AA:AA,'Hướng dẫn'!X:X) -> Crew neck classic

Sheet Gender
A1: Gender | B1: Name
A2: MEN | B2: Men
A3: WOM | B3: Women
A4: KID | B4: Kid
A5: UNI | B5: Unisex

Sheet Design
A1: Design | B1: Name
A2: FRA | B2: =_xlfn.XLOOKUP(A2,'Hướng dẫn'!AF:AF,'Hướng dẫn'!AD:AD) -> FRAME
A3: FST | B3: =_xlfn.XLOOKUP(A3,'Hướng dẫn'!AF:AF,'Hướng dẫn'!AD:AD) -> Flying Stock
A4: FLH | B4: =_xlfn.XLOOKUP(A4,'Hướng dẫn'!AF:AF,'Hướng dẫn'!AD:AD) -> Flying Fish
A5: CON | B5: =_xlfn.XLOOKUP(A5,'Hướng dẫn'!AF:AF,'Hướng dẫn'!AD:AD) -> Constable
A6: BAR | B6: =_xlfn.XLOOKUP(A6,'Hướng dẫn'!AF:AF,'Hướng dẫn'!AD:AD) -> Bardot
A7: STC | B7: =_xlfn.XLOOKUP(A7,'Hướng dẫn'!AF:AF,'Hướng dẫn'!AD:AD) -> Saigon Traffic
A8: CP1 | B8: =_xlfn.XLOOKUP(A8,'Hướng dẫn'!AF:AF,'Hướng dẫn'!AD:AD) -> CA PARADISE ZOOM LEFT
A9: SMP | B9: =_xlfn.XLOOKUP(A9,'Hướng dẫn'!AF:AF,'Hướng dẫn'!AD:AD) -> Star Map
A10: MIX | B10: =_xlfn.XLOOKUP(A10,'Hướng dẫn'!AF:AF,'Hướng dẫn'!AD:AD) -> Nhiều mẫu
A11: URB | B11: =_xlfn.XLOOKUP(A11,'Hướng dẫn'!AF:AF,'Hướng dẫn'!AD:AD) -> Urban
A12: TKU | B12: =_xlfn.XLOOKUP(A12,'Hướng dẫn'!AF:AF,'Hướng dẫn'!AD:AD) -> Truyen Kieu
A13: AUL | B13: =_xlfn.XLOOKUP(A13,'Hướng dẫn'!AF:AF,'Hướng dẫn'!AD:AD) -> Autumn Lion
... A539: A55 | B539: =_xlfn.XLOOKUP(A539,'Hướng dẫn'!AF:AF,'Hướng dẫn'!AD:AD) -> #N/A

Sheet Color
A1: Color | B1: Name
A2: MIX | B2: =_xlfn.XLOOKUP(A2,'Hướng dẫn'!AK:AK,'Hướng dẫn'!AI:AI) -> Màu Mix
A3: ORA | B3: =_xlfn.XLOOKUP(A3,'Hướng dẫn'!AK:AK,'Hướng dẫn'!AI:AI) -> Orange
A4: WHI | B4: =_xlfn.XLOOKUP(A4,'Hướng dẫn'!AK:AK,'Hướng dẫn'!AI:AI) -> White
A5: RGN | B5: =_xlfn.XLOOKUP(A5,'Hướng dẫn'!AK:AK,'Hướng dẫn'!AI:AI) -> Racing Green
A6: RED | B6: =_xlfn.XLOOKUP(A6,'Hướng dẫn'!AK:AK,'Hướng dẫn'!AI:AI) -> RE
A7: PUR | B7: =_xlfn.XLOOKUP(A7,'Hướng dẫn'!AK:AK,'Hướng dẫn'!AI:AI) -> Purple
A8: BLK | B8: =_xlfn.XLOOKUP(A8,'Hướng dẫn'!AK:AK,'Hướng dẫn'!AI:AI) -> BK
A9: JBG | B9: =_xlfn.XLOOKUP(A9,'Hướng dẫn'!AK:AK,'Hướng dẫn'!AI:AI) -> June Bug
A10: PIN | B10: =_xlfn.XLOOKUP(A10,'Hướng dẫn'!AK:AK,'Hướng dẫn'!AI:AI) -> Pink
A11: NAV | B11: =_xlfn.XLOOKUP(A11,'Hướng dẫn'!AK:AK,'Hướng dẫn'!AI:AI) -> NA
A12: SGR | B12: =_xlfn.XLOOKUP(A12,'Hướng dẫn'!AK:AK,'Hướng dẫn'!AI:AI) -> Steel Gray
A13: GRE | B13: =_xlfn.XLOOKUP(A13,'Hướng dẫn'!AK:AK,'Hướng dẫn'!AI:AI) -> Grey
... A121: HBN | B121: =_xlfn.XLOOKUP(A121,'Hướng dẫn'!AK:AK,'Hướng dẫn'!AI:AI) -> Havana Brown

Sheet Size
A1: Size | B1: Name
A2: 0 | B2: 0
A3: L | B3: L
A4: XXL | B4: XXL
A5: A3 | B5: A3
A6: M | B6: M
A7: 70x70 | B7: 70x70
A8: 10 | B8: 10
A9: S | B9: S
A10: 18CM | B10: 18CM
A11: AG | B11: A3/A4/A5
A12: 8 | B12: #N/A
... A66: 180g | B66: 180g

Sheet Hướng dẫn
A1: GINKGO VIETNAM
A3: PRODUCT LIST
A5: A. MÃ SKU
A6: VD: GO-M-PL-MA-LG-RP-M
A7: CÁC TRƯỜNG BẮT BUỘC | C7: CODE | D7: GIẢI MÃ | F7: SỐ KÝ TỰ
A8: 1 | B8: CHẤT LIỆU/MATERIAL | C8: GOR | D8: ORGANIC | F8: 3
A9: 2 | B9: GIỚI TÍNH/SEX | C9: MEN | D9: MEN | F9: 3
A10: 3 | B10: CHỦNG LOẠI/CATEGORIES | C10: POL | D10: POLO | F10: 3
A11: 4 | B11: KIỂU DÁNG/STYLE | C11: MSL | D11: MANDARIN SHORT SLEEVES | F11: 3
A12: 5 | B12: TÊN DESIGN | C12: LOG | D12: LOGO | F12: 3
A13: 6 | B13: MÀU SẮC | C13: RPL | D13: RED PLUM | F13: 3
A14: 7 | B14: SIZE | C14: M | D14: M | F14: 3
F15: Tổng 21 ký tự
B16: Các trường cách nhau bằng dấu gạch ngang "-"
A18: B. BẢNG MÃ CHI TIẾT.
A19: Quy tắc viết tắt
B20: Bỏ các từ phụ như “of”, “and”, “for”
B21: Lấy 1–3 chữ cái đầu của mỗi từ chính, nếu trùng thì lấy 2 chữ cái đầu và 1 chữ cái cuối
B22: Tổng mã dài 3 ký tự
A24: HÌNH THỨC KINH DOANH | F24: 1.LOẠI VẢI/ MATERIAL/ SUPPLIERS | K24: 2. GIỚI TÍNH/GENDER | Q24: 3. CHỦNG LOẠI/ CATEGORIES | W24: 4. CHỦNG LOẠI KIỂU DÁNG CHI TIẾT/STYLE | AC24: 5.THIẾT KẾ/DESIGN | AH24: 6. MÀU SẮC/ COLOR | AL24: 7. SIZE
A25: NO | B25: NAME | C25: TÊN TIẾNG VIỆT | D25: CODE | E25: EXAMPLE/GHI CHÚ | F25: NO | G25: FABRIC NAME | H25: CODE CŨ | I25: CODE MỚI | J25: EXAMPLE/GHI CHÚ | K25: NO | L25: NAME | M25: CODE CŨ | N25: CODE MỚI | O25: GHI CHÚ | Q25: NO | R25: NAME | S25: TÊN TIẾNG VIỆT | T25: CODE | U25: CODE MỚI | V25: NOTE | W25: NO | X25: STYLE NAME | Y25: TÊN TIẾNG VIỆT | Z25: CODE | AA25: CODE MỚI | AB25: EXAMPLE/GHI CHÚ | AC25: NO | AD25: NAME | AE25: CODE | AF25: CODE MỚI | AG25: NOTE | AH25: NO | AI25: NAME | AJ25: CODE CŨ | AK25: CODE MỚI | AL25: NO | AM25: NAME | AN25: CODE CŨ
A26: 1 | B26: Self-Manufactured / In-house Production | C26: Ginkgo sản xuất | D26: GPR | F26: 1 | G26: Organic | H26: GO | I26: GOR | K26: 1 | L26: Men | M26: M | N26: MEN | O26: nam | P26: APPAREL | Q26: TOP | W26: I> | X26: TOP | AC26: 1_GK | AD26: Abstract Calligraphy | AE26: AC | AF26: ACY | AG26: Stop | AH26: DSP | AI26: Havana Black | AJ26: HA BK | AK26: HBK | AL26: 1 | AM26: 2 | AN26: 2
A27: 2 | B27: Co-production / Collaborative Production | C27: Hợp tác sản xuất | D27: GCO | E27: Kết hợp với đối tác để đồng sở hữu | F27: 2 | G27: Special | H27: GS | I27: GSL | K27: 2 | L27: Women | M27: W | N27: WOM | O27: nữ | Q27: 1 | R27: Polo Short sleeves | S27: Áo phông cổ bẻ tay lỡ | T27: PL | U27: POL | W27: 1 | X27: Mandarin Collar | Y27: cổ đứng | Z27: MA | AA27: MAN | AB27: MA | AC27: 1_GK | AD27: Abundance | AE27: AB | AF27: ABU | AG27: Stop | AH27: DSP | AI27: HM Orange | AJ27: HM OR | AK27: HOE | AL27: 2 | AM27: 4 | AN27: 4
A28: 3 | B28: Wholesale Purchase / Outright Purchase | C28: Mua đứt | D28: CPU | F28: 3 | G28: Supima | H28: GM | I28: GSU | K28: 3 | L28: Kid | M28: K | N28: KID | O28: trẻ em | Q28: 2 | R28: T-Shirt Short Sleeves | S28: Áo thun ngắn tay | T28: SS | U28: TSS | W28: 2 | X28: Classic Collar | Y28: cổ thường | Z28: CL | AA28: CLA | AB28: CL | AC28: 1_GK | AD28: Alphabet | AE28: AL | AF28: ALP | AG28: Stop | AH28: DSP | AI28: Natural | AJ28: NAT | AK28: NAT | AL28: 3 | AM28: 6 | AN28: 6
A29: 4 | B29: Consignment | C29: Ký gửi | D29: CCO | F29: 4 | G29: Spandex | H29: GP | I29: GSP | K29: 4 | L29: Unisex | M29: UN | N29: UNI | Q29: 3 | R29: Top midi sleeves | S29: Áo thun tay lỡ | T29: MS | U29: TSM | V29: Red Daisy Pique | W29: 3 | X29: Button-down Collar | Y29: cổ thường có nút | Z29: BD | AA29: BUT | AC29: 1_GK | AD29: Aphrodite | AE29: APH | AF29: APH | AH29: DSP | AI29: Purple | AJ29: PU | AK29: PUR | AL29: 4 | AM29: 8 | AN29: 8
F30: 5 | G30: Basic | H30: GB | I30: GBA | Q30: 4 | R30: T-shirts long sleeves | S30: Áo thun dài tay | T30: TLS | U30: TSL | W30: 4 | X30: Ribban | Y30: cổ bo gân | Z30: RI | AA30: RIB | AC30: 1_GK | AD30: Autumn Lion | AE30: AUL | AF30: AUL | AH30: GK | AI30: ??????? | AJ30: FG | AK30: FG | AL30: 5 | AM30: 10 | AN30: 10
F31: 6 | G31: Classic | H31: GCL | I31: GCL | J31: Dành cho 1 số mẫu Oversize | Q31: 5 | R31: T-Shirt Oversized | S31: Áo thun dáng rộng | T31: OS | U31: TSO | W31: 5 | X31: Crew neck classic | Y31: cổ tròn | Z31: O | AA31: ONE | AC31: 1_GK | AD31: Bali Lion | AE31: BLN | AF31: BLN | AH31: GK | AI31: ???????? | AJ31: ST | AK31: ST | AL31: 6 | AM31: 12 | AN31: 12
F32: 7 | G32: Cotton Veil | H32: GC | I32: GCV | Q32: 6 | R32: T-shirts Pocket Short Sleeves | S32: Áo thun có túi tay ngắn | T32: PO | U32: TSP | W32: 6 | X32: High crew neck classic | Y32: cổ tròn cao | Z32: HCN | AA32: HNE | AC32: 1_GK | AD32: Banana Leaf | AE32: BF | AF32: BLF | AG32: Running Item | AH32: GK | AI32: Almond Toast | AJ32: AL | AK32: ATT | AL32: 7 | AM32: XS | AN32: XS
F33: 8 | G33: Khaki | H33: GK | I33: GKK | Q33: 7 | R33: T-Shirt Open Back | S33: Áo thun xẻ sau tay ngắn | T33: SSS | U33: TSB | V33: Hàng Hoa | W33: 7 | X33: Double Crew Neck | Y33: cổ tròn kép | Z33: D | AA33: DNE | AC33: 1_GK | AD33: Banh Chung | AE33: BC | AF33: BCG | AG33: Stop | AH33: GK | AI33: Almond Toast | AJ33: AT | AK33: ATT | AL33: 8 | AM33: S | AN33: S
F34: 9 | G34: Pique | H34: GPI | I34: GPI | Q34: 8 | R34: Apple | S34: Áo trái táo | T34: AP | U34: APP | W34: 8 | X34: V-neck | Y34: cổ chữ V | Z34: V | AA34: VNE | AC34: 1_GK | AD34: Basket Sweater | AE34: BTS | AF34: BTS | AH34: GK | AI34: Amber Gold | AJ34: AG | AK34: AGD | AL34: 9 | AM34: M | AN34: M
F35: 10 | G35: Fish Skin Import | H35: GFI | I35: GFI | Q35: 9 | R35: Freesize | S35: Áo cổ thuyền dáng Free | T35: FZ | U35: FZE | V35: Free Size | W35: 9 | X35: Boat Neck | Y35: cổ thuyền | Z35: M | AA35: BNE | AB35: Mã cũ : cổ M | AC35: 1_GK | AD35: Bất Tiện | AE35: BT | AF35: BTN | AG35: Stop | AH35: GK | AI35: Army | AJ35: AR | AK35: ARM | AL35: 10 | AM35: L | AN35: L
F36: 11 | G36: Fish Skin | H36: GF | I36: GFN | Q36: 10 | R36: Zipper Top | S36: Áo ngắn tay có khóa kéo ở ngực | T36: ZT | U36: ZTP | W36: 10 | X36: Double-Sided Crew Neck classic | Y36: cổ tròn mặc được cả 2 mặt | Z36: DS | AA36: INE | AC36: 1_GK | AD36: Beach People | AE36: BP | AF36: BEP | AG36: Stop | AH36: GK | AI36: Ash Brown | AJ36: AB | AK36: ABN | AL36: 11 | AM36: XL | AN36: XL
F37: 12 | G37: Linen | H37: GL | I37: GLI | Q37: 11 | R37: Plus Size | S37: Áo cổ tròn dáng Plus size | T37: PZ | U37: PZE | W37: 11 | X37: U neck | Y37: cổ U | Z37: U | AA37: UNE | AC37: 1_GK | AD37: Bear | AE37: BE | AF37: BEA | AG37: Stop | AH37: GK | AI37: Asphalt | AJ37: AS | AK37: AST | AL37: 12 | AM37: XXL | AN37: XXL
F38: 13 | G38: Canvas | H38: GCA | I38: GCA | Q38: 12 | R38: Shell top | S38: Áo cổ tròn dáng con sò | T38: ST | U38: STP | W38: 12 | X38: Off-Shoulder | Y38: trễ vai | Z38: M | AA38: OFF | AB38: Mã cũ : cổ M | AC38: 1_GK | AD38: Beep Beep | AE38: BB | AF38: BBP | AG38: Seasonal | AH38: DSP | AI38: Baby Blue | AJ38: BB BL | AK38: BBL | AL38: 13 | AM38: FZ1 | AN38: FZ1
F39: 14 | G39: Super Soft | H39: GSF | I39: GSF | J39: Dừng sản xuất | Q39: 13 | R39: Rectangle pocket | S39: Áo vuông có túi | T39: RT | U39: RPT | W39: II> | X39: BOTTOM | AC39: 1_GK | AD39: Beer | AE39: BEE | AF39: BEE | AG39: Stop | AH39: DSP | AI39: Baby Blue | AJ39: BBL | AK39: BBL | AL39: 14 | AM39: FZ2 | AN39: FZ2
F40: 15 | G40: Cotton Twill | H40: GCT | I40: GCT | J40: Dừng sản xuất | Q40: 14 | R40: Shirt Short Sleeves | S40: Áo sơ mi tay ngắn | T40: SHI | U40: SIS | W40: 1 | X40: Elastic Waist | Y40: lưng thun | Z40: EB | AA40: EBT | AC40: 1_GK | AD40: Beer Pop | AE40: BP | AF40: BPP | AG40: Seasonal | AH40: DSP | AI40: Baby Blue Black Dot | AJ40: BBBD | AK40: 3BD | AL40: 15 | AM40: 36 | AN40: 36
F41: 16 | G41: Visco | H41: GV | I41: GVI | J41: Dừng sản xuất | Q41: 15 | R41: Shirt Long Sleeves | S41: Áo sơ mi tay dài | T41: SHI | U41: SIL | W41: 2 | X41: Flat-Front | Y41: cạp cúc lưng thun sau | Z41: FL | AA41: FBT | AC41: 1_GK | AD41: Bird | AE41: BI | AF41: BIR | AG41: Stop | AH41: DSP | AI41: Baby Pink | AJ41: BPK | AK41: BPK | AL41: 16
F42: 17 | G42: Café | H42: GCF | I42: GCF | Q42: 16 | R42: Blouse Long Sleeves | S42: Áo sơ mi tay dài | T42: BLS | U42: BLS | W42: 3 | X42: Drawstring Waist | Y42: lưng dây rút | Z42: DW | AA42: DBT | AC42: 1_GK | AD42: Bit Mat Bat De | AE42: BM | AF42: BIT | AG42: Stop | AH42: N'GO | AI42: Beige Sunflower | AJ42: BS | AK42: BSR | AL42: 17 | AM42: 39 | AN42: 39
F43: 18 | G43: Eddy Bags | H43: EC | I43: ECB | Q43: 17 | R43: Blouse Short Sleeves | S43: Áo sơ mi tay ngắn | T43: OS | U43: BLL | W43: 4 | X43: Button Waist | Y43: lưng cúc | Z43: BW | AA43: BBT | AC43: 1_GK | AD43: Bow Scrunchie | AE43: BSE | AF43: BSE | AH43: DSP | AI43: BK | AJ43: BK | AK43: BLK | AL43: 18 | AM43: 40 | AN43: 40
F44: 19 | G44: Bạc Liêu | H44: BL | I44: BLS | Q44: 18 | R44: Blouse Long Sleeves Asymmetrical | S44: Áo sơ mi bất đối xứng | T44: LST | U44: BLA | W44: III> | X44: HEAD WEAR | Z44: HWR | AA44: HWR | AC44: 1_GK | AD44: Buddhaline | AE44: BL | AF44: BUD | AG44: Stop | AH44: DSP | AI44: Black | AJ44: BLK | AK44: BLK | AL44: 19 | AM44: 41 | AN44: 41
...
